
CondaError: Run 'conda init' before 'conda activate'

/software/hgi/envs/conda/team354/xl7/topiary/lib/python3.11/site-packages/Bio/Application/__init__.py:39: BiopythonDeprecationWarning: The Bio.Application modules and modules relying on it have been deprecated.

Due to the on going maintenance burden of keeping command line application
wrappers up to date, we have decided to deprecate and eventually remove these
modules.

We instead now recommend building your command line and invoking it directly
with the subprocess module.
  warnings.warn(
  0%|          | 0/360 [00:00<?, ?it/s]  0%|          | 1/360 [00:00<03:44,  1.60it/s]  1%|          | 3/360 [00:01<03:05,  1.92it/s]  2%|▏         | 7/360 [00:06<05:32,  1.06it/s]  2%|▏         | 8/360 [00:07<06:16,  1.07s/it]  2%|▎         | 9/360 [00:08<05:45,  1.02it/s]  3%|▎         | 10/360 [00:14<13:21,  2.29s/it]  3%|▎         | 11/360 [00:33<37:11,  6.39s/it]  3%|▎         | 12/360 [00:42<40:36,  7.00s/it]  4%|▍         | 16/360 [01:22<51:04,  8.91s/it]  9%|▉         | 34/360 [02:07<20:38,  3.80s/it] 14%|█▍        | 52/360 [02:44<14:43,  2.87s/it] 20%|█▉        | 71/360 [03:09<10:29,  2.18s/it] 24%|██▍       | 88/360 [03:57<10:57,  2.42s/it] 29%|██▉       | 104/360 [04:00<07:13,  1.69s/it] 29%|██▉       | 106/360 [05:42<18:40,  4.41s/it] 39%|███▉      | 142/360 [06:07<08:05,  2.23s/it] 40%|███▉      | 143/360 [07:18<13:44,  3.80s/it] 40%|████      | 144/360 [07:35<15:07,  4.20s/it] 54%|█████▍    | 196/360 [08:05<04:32,  1.66s/it] 55%|█████▍    | 197/360 [08:07<04:33,  1.68s/it] 59%|█████▉    | 214/360 [09:38<06:52,  2.83s/it] 64%|██████▍   | 232/360 [10:41<06:30,  3.05s/it] 70%|██████▉   | 251/360 [10:49<03:58,  2.18s/it] 70%|███████   | 252/360 [11:00<04:19,  2.40s/it] 74%|███████▍  | 268/360 [11:41<03:45,  2.45s/it] 79%|███████▉  | 286/360 [12:29<03:06,  2.53s/it] 84%|████████▍ | 304/360 [12:34<01:38,  1.76s/it] 85%|████████▌ | 306/360 [12:38<01:36,  1.78s/it] 89%|████████▉ | 322/360 [14:10<02:03,  3.25s/it] 90%|████████▉ | 323/360 [14:22<02:10,  3.53s/it] 90%|█████████ | 324/360 [14:41<02:31,  4.20s/it] 99%|█████████▉| 358/360 [15:32<00:04,  2.37s/it]100%|██████████| 360/360 [15:32<00:00,  2.59s/it]
Traceback (most recent call last):
  File "/software/hgi/envs/conda/team354/xl7/topiary/lib/python3.11/site-packages/topiary/_private/interface.py", line 32, in wrapper
    value = func(*args, **kwargs)
            ^^^^^^^^^^^^^^^^^^^^^
  File "/software/hgi/envs/conda/team354/xl7/topiary/lib/python3.11/site-packages/topiary/raxml/tree.py", line 78, in generate_ml_tree
    supervisor.create_calc_dir(calc_dir=calc_dir,
  File "/software/hgi/envs/conda/team354/xl7/topiary/lib/python3.11/site-packages/topiary/_private/supervisor.py", line 282, in create_calc_dir
    self._df = topiary.read_dataframe(input_df)
               ^^^^^^^^^^^^^^^^^^^^^^^^^^^^^^^^
  File "/software/hgi/envs/conda/team354/xl7/topiary/lib/python3.11/site-packages/topiary/io/dataframe.py", line 44, in read_dataframe
    df = pd.read_csv(filename,sep=",")
         ^^^^^^^^^^^^^^^^^^^^^^^^^^^^^
  File "/software/hgi/envs/conda/team354/xl7/topiary/lib/python3.11/site-packages/pandas/io/parsers/readers.py", line 1026, in read_csv
    return _read(filepath_or_buffer, kwds)
           ^^^^^^^^^^^^^^^^^^^^^^^^^^^^^^^
  File "/software/hgi/envs/conda/team354/xl7/topiary/lib/python3.11/site-packages/pandas/io/parsers/readers.py", line 626, in _read
    return parser.read(nrows)
           ^^^^^^^^^^^^^^^^^^
  File "/software/hgi/envs/conda/team354/xl7/topiary/lib/python3.11/site-packages/pandas/io/parsers/readers.py", line 1923, in read
    ) = self._engine.read(  # type: ignore[attr-defined]
        ^^^^^^^^^^^^^^^^^^^^^^^^^^^^^^^^^^^^^^^^^^^^^^^^
  File "/software/hgi/envs/conda/team354/xl7/topiary/lib/python3.11/site-packages/pandas/io/parsers/c_parser_wrapper.py", line 234, in read
    chunks = self._reader.read_low_memory(nrows)
             ^^^^^^^^^^^^^^^^^^^^^^^^^^^^^^^^^^^
  File "parsers.pyx", line 838, in pandas._libs.parsers.TextReader.read_low_memory
  File "parsers.pyx", line 905, in pandas._libs.parsers.TextReader._read_rows
  File "parsers.pyx", line 874, in pandas._libs.parsers.TextReader._tokenize_rows
  File "parsers.pyx", line 891, in pandas._libs.parsers.TextReader._check_tokenize_status
  File "parsers.pyx", line 2061, in pandas._libs.parsers.raise_parser_error
pandas.errors.ParserError: Error tokenizing data. C error: EOF inside string starting at row 258

The above exception was the direct cause of the following exception:

Traceback (most recent call last):
  File "/software/hgi/envs/conda/team354/xl7/topiary/lib/python3.11/site-packages/topiary/_private/interface.py", line 32, in wrapper
    value = func(*args, **kwargs)
            ^^^^^^^^^^^^^^^^^^^^^
  File "/software/hgi/envs/conda/team354/xl7/topiary/lib/python3.11/site-packages/topiary/pipeline/alignment_to_ancestors.py", line 343, in alignment_to_ancestors
    topiary.generate_ml_tree(prev_calculation=prev_calculation,
  File "/software/hgi/envs/conda/team354/xl7/topiary/lib/python3.11/site-packages/topiary/_private/interface.py", line 38, in wrapper
    raise WrappedFunctionException(err) from e
topiary._private.interface.WrappedFunctionException: 

Caught exception in function 'generate_ml_tree'. Returning to starting
directory and cleaning up. Check error stack for cause of
this error.



The above exception was the direct cause of the following exception:

Traceback (most recent call last):
  File "/software/hgi/envs/conda/team354/xl7/topiary/lib/python3.11/site-packages/topiary/_private/wrap.py", line 185, in wrap_function
    ret = fcn(**fcn_args.__dict__)
          ^^^^^^^^^^^^^^^^^^^^^^^^
  File "/software/hgi/envs/conda/team354/xl7/topiary/lib/python3.11/site-packages/topiary/_private/interface.py", line 38, in wrapper
    raise WrappedFunctionException(err) from e
topiary._private.interface.WrappedFunctionException: 

Caught exception in function 'alignment_to_ancestors'. Returning to starting
directory and cleaning up. Check error stack for cause of
this error.



The above exception was the direct cause of the following exception:

Traceback (most recent call last):
  File "/software/hgi/envs/conda/team354/xl7/topiary/bin/topiary-alignment-to-ancestors", line 26, in <module>
    main()
  File "/software/hgi/envs/conda/team354/xl7/topiary/bin/topiary-alignment-to-ancestors", line 21, in main
    wrap_function(alignment_to_ancestors,
  File "/software/hgi/envs/conda/team354/xl7/topiary/lib/python3.11/site-packages/topiary/_private/wrap.py", line 189, in wrap_function
    raise RuntimeError(err) from e
RuntimeError: 

Function alignment_to_ancestors raised an error.

To see command line help, run topiary-alignment-to-ancestors --help


